File: #2212211_DevA1-FM7inj-FM8-NL_10K_AS03_0p5mA_offset+73p75mV_5spm4_50rdg_100plc_230217.dat
[Header]
TITLE, default name
FILEOPENTIME, 34996355.38, 2/17/2023, 5:10 PM
BYAPP, Resistivity, 2.0, 1.0
INFO, APPNAME, PPMS MultiVu Application, Release 1.5.0.19
INFO, , Sample1 Name
INFO, 1, Sample1 Cross Section
INFO, 1, Sample1 Length
INFO, Ohm-m, Sample1 Units
INFO, , Sample2 Name
INFO, 1, Sample2 Cross Section
INFO, 1, Sample2 Length
INFO, Ohm-m, Sample2 Units
INFO, , Sample3 Name
INFO, 1, Sample3 Cross Section
INFO, 1, Sample3 Length
INFO, Ohm-m, Sample3 Units
INFO, , Sample4 Name
INFO, 1, Sample4 Cross Section
INFO, 1, Sample4 Length
INFO, Ohm-m, Sample4 Units
FIELDGROUP, Resistivity,2,3,4,5,6,7,8,9,10,11,12,13,14,15,16,17,18,19,20,21,22,23,24,25,26,27,28,29,30,31,32,33,34,35,36,37,38,39,40,41
STARTUPGROUP, Resistivity
STARTUPAXIS, X, 2, LINEAR, AUTO
STARTUPAXIS, Y1, 7, LINEAR, AUTO
STARTUPAXIS, Y2, 9, LINEAR, AUTO
STARTUPAXIS, Y3, 11, LINEAR, AUTO
PLOT_APPEARANCE, ALL, HORZ_GRID_ON, VERT_GRID_ON, MARKERS_AND_LINES, ALL_LINES
DATATYPE, TIME, 2
DATATYPE, COMMENT, 1
[Data]
Comment,Time Stamp (sec),Status (code),Temperature (K),Magnetic Field (Oe),Sample Position (deg),Bridge 1 Resistivity (Ohm-m),Bridge 1 Excitation (uA),Bridge 2 Resistivity (Ohm-m),Bridge 2 Excitation (uA),Bridge 3 Resistivity (Ohm-m),Bridge 3 Excitation (uA),Bridge 4 Resistivity (Ohm-m),Bridge 4 Excitation (uA),Bridge 1 Std. Dev. (Ohm-m),Bridge 2 Std. Dev. (Ohm-m),Bridge 3 Std. Dev. (Ohm-m),Bridge 4 Std. Dev. (Ohm-m),Number of Readings,Bridge 1 Resistance (Ohms),Bridge 2 Resistance (Ohms),Bridge 3 Resistance (Ohms),Bridge 4 Resistance (Ohms),Signal 1 Vin (V),Signal 2 Vin (V),Digital Inputs (code),Drive 1 Iout (mA),Drive 1 Ipower (watts),Drive 2 Iout (mA),Drive 2 Ipower (watts),Pressure (),Map 20 (),Map 21 (),Map 22 (),Map 23 (),Map 24 (),Map 25 (),Map 26 (),Map 27 (),Map 28 (),Map 29 ()
,34996409.80,69953,10.0001497268677,-400.075157470703,90.0139999389648,,,,,,,,,,,,,0,,,,,,0.2931,,,,,,,,,,
,34996730.72,69953,9.99924993515015,-355.094760742187,90.0139999389648,,,,,,,,,,,,,0,,,,,,0.2589,,,,,,,,,,
,34997044.34,69953,10.0002002716064,-309.972640380859,90.0139999389648,,,,,,,,,,,,,0,,,,,,0.4787,,,,,,,,,,
,34997379.98,69953,9.99985027313232,-265.089919433594,90.0139999389648,,,,,,,,,,,,,0,,,,,,0.5276,,,,,,,,,,
,34997706.16,4417,9.99965000152588,-220.109279785156,90.0139999389648,,,,,,,,,,,,,0,,,,,,0.3762,,,,,,,,,,
,34998026.16,69953,10,-175.095520019531,90.0139999389648,,,,,,,,,,,,,0,,,,,,0.4543,,,,,,,,,,
,34998341.39,69953,10.0002503395081,-130.001359863281,90.0139999389648,,,,,,,,,,,,,0,,,,,,0.4152,,,,,,,,,,
,34998669.06,4417,9.99959993362427,-84.9677597045898,90.0139999389648,,,,,,,,,,,,,0,,,,,,0.3175,,,,,,,,,,
,34998983.56,69953,10.0002498626709,-40.0467599487305,90.0139999389648,,,,,,,,,,,,,0,,,,,,0.2882,,,,,,,,,,
,34999305.13,69953,9.99989986419678,5.17559999465942,90.0139999389648,,,,,,,,,,,,,0,,,,,,0.0782,,,,,,,,,,
,34999639.61,69953,9.99970006942749,49.9049198913574,90.0139999389648,,,,,,,,,,,,,0,,,,,,0.3273,,,,,,,,,,
,34999946.92,69953,10.0006499290466,95.0677993774414,90.0139999389648,,,,,,,,,,,,,0,,,,,,-0.1612,,,,,,,,,,
,35000267.13,69953,10.0002498626709,139.907080078125,90.0139999389648,,,,,,,,,,,,,0,,,,,,-2.1837,,,,,,,,,,
,35000588.91,69953,10.0005497932434,184.899077758789,90.0139999389648,,,,,,,,,,,,,0,,,,,,-2.0322,,,,,,,,,,
,35000909.59,69953,10.0001502037048,229.946920776367,90.0139999389648,,,,,,,,,,,,,0,,,,,,0.5227,,,,,,,,,,
,35001223.44,4417,9.99945020675659,275.018482666016,90.0139999389648,,,,,,,,,,,,,0,,,,,,0.4690,,,,,,,,,,
,35001537.63,69953,10.0001001358032,319.998878173828,90.0139999389648,,,,,,,,,,,,,0,,,,,,0.3322,,,,,,,,,,
,35001844.13,69953,10.000599861145,364.919641113281,90.0139999389648,,,,,,,,,,,,,0,,,,,,0.3810,,,,,,,,,,
,35002144.22,4417,9.99965000152588,395.091199951172,90.0139999389648,,,,,,,,,,,,,0,,,,,,0.2980,,,,,,,,,,
,35002451.89,69953,10.0005502700806,350.036721191406,90.0139999389648,,,,,,,,,,,,,0,,,,,,0.2931,,,,,,,,,,
,35002772.77,69953,9.99994993209839,305.124560546875,90.0139999389648,,,,,,,,,,,,,0,,,,,,0.1905,,,,,,,,,,
,35003093.91,4417,9.99959993362427,260.046278076172,90.0139999389648,,,,,,,,,,,,,0,,,,,,0.2589,,,,,,,,,,
,35003408.28,69953,9.99989986419678,215.127080688477,90.0139999389648,,,,,,,,,,,,,0,,,,,,0.2687,,,,,,,,,,
,35003715.17,69953,9.99989986419678,170.097800292969,90.0139999389648,,,,,,,,,,,,,0,,,,,,0.3615,,,,,,,,,,
,35004036.11,69953,9.99984979629517,125.150440673828,90.0139999389648,,,,,,,,,,,,,0,,,,,,0.1026,,,,,,,,,,
,35004342.98,69953,9.99994993209839,80.0916397094727,90.0139999389648,,,,,,,,,,,,,0,,,,,,-0.0537,,,,,,,,,,
,35004663.55,69953,9.99985027313232,35.0772402954102,90.0139999389648,,,,,,,,,,,,,0,,,,,,-0.0098,,,,,,,,,,
,35004984.77,69953,10.0002999305725,-9.8938000869751,90.0139999389648,,,,,,,,,,,,,0,,,,,,0.0293,,,,,,,,,,
,35005292.53,69953,9.99994993209839,-54.9534799194336,90.0139999389648,,,,,,,,,,,,,0,,,,,,0.0489,,,,,,,,,,
,35005605.52,4417,10.0003499984741,-100.006199951172,90.0139999389648,,,,,,,,,,,,,0,,,,,,-2.1886,,,,,,,,,,
,35005912.44,69953,10.0000495910645,-145.019559326172,90.0139999389648,,,,,,,,,,,,,0,,,,,,-2.2960,,,,,,,,,,
,35006226.78,69953,10,-189.87032043457,90.0139999389648,,,,,,,,,,,,,0,,,,,,0.3664,,,,,,,,,,
,35006549.05,4417,10.0001001358032,-234.96,90.0139999389648,,,,,,,,,,,,,0,,,,,,0.3957,,,,,,,,,,
,35006871.00,69953,9.99979972839355,-279.853120117187,90.0139999389648,,,,,,,,,,,,,0,,,,,,0.2785,,,,,,,,,,
,35007177.55,69953,10.0002999305725,-324.917800292969,90.0139999389648,,,,,,,,,,,,,0,,,,,,0.2882,,,,,,,,,,
,35007499.55,4417,10.0006999969482,-369.920441894531,90.0139999389648,,,,,,,,,,,,,0,,,,,,0.0586,,,,,,,,,,
,35007828.34,69953,10.0002999305725,-390.122199707031,90.0139999389648,,,,,,,,,,,,,0,,,,,,-0.1759,,,,,,,,,,
,35008155.30,69953,10.0002498626709,-345.131721191406,90.0139999389648,,,,,,,,,,,,,0,,,,,,-0.1075,,,,,,,,,,
,35008476.48,4417,9.99965000152588,-300.007319335938,90.0139999389648,,,,,,,,,,,,,0,,,,,,0.2003,,,,,,,,,,
,35008796.41,69953,10.0001497268677,-254.999119262695,90.0139999389648,,,,,,,,,,,,,0,,,,,,0.0830,,,,,,,,,,
,35009103.59,69953,10.0001001358032,-210.03796081543,90.0139999389648,,,,,,,,,,,,,0,,,,,,0.1466,,,,,,,,,,
,35009438.98,69953,10.0001997947693,-165.070560913086,90.0139999389648,,,,,,,,,,,,,0,,,,,,0.6204,,,,,,,,,,
,35009752.92,69953,10.0003499984741,-119.98951965332,90.0139999389648,,,,,,,,,,,,,0,,,,,,0.7670,,,,,,,,,,
,35010066.20,4417,9.99985027313232,-75.09916015625,90.0139999389648,,,,,,,,,,,,,0,,,,,,0.0049,,,,,,,,,,
,35010373.56,69953,10.0005497932434,-30.1022798919678,90.0139999389648,,,,,,,,,,,,,0,,,,,,0.3322,,,,,,,,,,
,35010694.78,69953,9.99995040893555,14.9425998687744,90.0139999389648,,,,,,,,,,,,,0,,,,,,0.2785,,,,,,,,,,
,35011008.72,4417,10.0000500679016,59.9874798583984,90.0139999389648,,,,,,,,,,,,,0,,,,,,0.3322,,,,,,,,,,
,35011316.47,69953,10.0001997947693,104.912799377441,90.0139999389648,,,,,,,,,,,,,0,,,,,,-2.1690,,,,,,,,,,
,35011630.69,69953,9.99995040893555,149.857200317383,90.0139999389648,,,,,,,,,,,,,0,,,,,,-2.0078,,,,,,,,,,
,35011951.22,4417,10,194.999440307617,90.0139999389648,,,,,,,,,,,,,0,,,,,,0.4885,,,,,,,,,,
,35012264.78,69953,10,239.945079345703,90.0139999389648,,,,,,,,,,,,,0,,,,,,0.4201,,,,,,,,,,
,35012585.28,69953,9.9997501373291,285.023836669922,90.0139999389648,,,,,,,,,,,,,0,,,,,,0.4494,,,,,,,,,,
,35012906.11,4417,10,329.906240234375,90.0139999389648,,,,,,,,,,,,,0,,,,,,0.3078,,,,,,,,,,
,35013219.30,69953,10.0004000663757,374.926798095703,90.0139999389648,,,,,,,,,,,,,0,,,,,,0.3420,,,,,,,,,,
,35013526.22,69953,9.99980020523071,385.077961425781,90.0139999389648,,,,,,,,,,,,,0,,,,,,0.4152,,,,,,,,,,
,35013862.81,69953,9.99969959259033,340.071558837891,90.0139999389648,,,,,,,,,,,,,0,,,,,,0.2687,,,,,,,,,,
,35014177.20,69953,10.0001997947693,295.059600830078,90.0139999389648,,,,,,,,,,,,,0,,,,,,0.1563,,,,,,,,,,
,35014504.02,69953,10,250.066481323242,90.0139999389648,,,,,,,,,,,,,0,,,,,,0.2247,,,,,,,,,,
,35014817.63,69953,10.0001502037048,205.066798706055,90.0139999389648,,,,,,,,,,,,,0,,,,,,0.3273,,,,,,,,,,
,35015138.44,69953,10.0003499984741,160.002960205078,90.0139999389648,,,,,,,,,,,,,0,,,,,,0.2149,,,,,,,,,,
,35015472.64,4417,10.0000500679016,114.993519897461,90.0139999389648,,,,,,,,,,,,,0,,,,,,0.2491,,,,,,,,,,
,35015793.28,69953,10.0001001358032,70.1027603149414,90.0139999389648,,,,,,,,,,,,,0,,,,,,0.2931,,,,,,,,,,
,35016108.66,69953,9.99979972839355,25.062320022583,90.0139999389648,,,,,,,,,,,,,0,,,,,,0.2345,,,,,,,,,,
,35016429.53,4417,10.0001502037048,-20.0259600830078,90.0139999389648,,,,,,,,,,,,,0,,,,,,0.2833,,,,,,,,,,
,35016744.52,69953,9.99970006942749,-64.9229598999023,90.0139999389648,,,,,,,,,,,,,0,,,,,,0.1612,,,,,,,,,,
,35017058.69,69953,9.99944972991943,-109.938639831543,90.0139999389648,,,,,,,,,,,,,0,,,,,,-2.1641,,,,,,,,,,
,35017373.56,69953,9.99984979629517,-154.987682495117,90.0139999389648,,,,,,,,,,,,,0,,,,,,-2.2667,,,,,,,,,,
,35017681.09,69953,10.0002999305725,-199.812598876953,90.0139999389648,,,,,,,,,,,,,0,,,,,,0.0733,,,,,,,,,,
,35018008.84,4417,10,-244.842321166992,90.0139999389648,,,,,,,,,,,,,0,,,,,,0.1466,,,,,,,,,,
,35018322.20,69953,9.99984979629517,-289.889998779297,90.0139999389648,,,,,,,,,,,,,0,,,,,,0.1368,,,,,,,,,,
,35018644.19,69953,10.0004501342773,-334.947559814453,90.0139999389648,,,,,,,,,,,,,0,,,,,,0.2443,,,,,,,,,,
,35018972.88,4417,9.99935007095337,-380.049517822266,90.0139999389648,,,,,,,,,,,,,0,,,,,,0.3762,,,,,,,,,,
,35019286.09,69953,9.99965000152588,-380.067280273438,90.0139999389648,,,,,,,,,,,,,0,,,,,,0.3566,,,,,,,,,,
,35019606.44,69953,10.0002498626709,-334.956241455078,90.0139999389648,,,,,,,,,,,,,0,,,,,,0.4983,,,,,,,,,,
,35019926.77,69953,10,-290.096917724609,90.0139999389648,,,,,,,,,,,,,0,,,,,,0.2833,,,,,,,,,,
,35020248.08,69953,9.99989986419678,-245.039760131836,90.0139999389648,,,,,,,,,,,,,0,,,,,,0.2247,,,,,,,,,,
,35020567.48,69953,10,-199.979719848633,90.0139999389648,,,,,,,,,,,,,0,,,,,,0.3762,,,,,,,,,,
,35020888.55,69953,10.0005497932434,-155.001239624023,90.0139999389648,,,,,,,,,,,,,0,,,,,,0.4543,,,,,,,,,,
,35021209.66,69953,10.0000996589661,-110.030039978027,90.0139999389648,,,,,,,,,,,,,0,,,,,,0.4592,,,,,,,,,,
,35021516.50,4417,9.99935007095337,-65.0903198242188,90.0139999389648,,,,,,,,,,,,,0,,,,,,0.4397,,,,,,,,,,
,35021830.69,69953,9.9997501373291,-20.0312400054932,90.0139999389648,,,,,,,,,,,,,0,,,,,,0.2149,,,,,,,,,,
,35022159.59,69953,9.99965000152588,24.8943199157715,90.0139999389648,,,,,,,,,,,,,0,,,,,,0.3420,,,,,,,,,,
,35022472.89,4417,9.99985027313232,69.940520324707,90.0139999389648,,,,,,,,,,,,,0,,,,,,0.3322,,,,,,,,,,
,35022787.81,69953,9.99980020523071,114.889000244141,90.0139999389648,,,,,,,,,,,,,0,,,,,,-2.0518,,,,,,,,,,
,35023115.36,69953,10.0002498626709,159.999438476562,90.0139999389648,,,,,,,,,,,,,0,,,,,,-2.2130,,,,,,,,,,
,35023429.44,4417,9.99965000152588,204.955079345703,90.0139999389648,,,,,,,,,,,,,0,,,,,,0.5129,,,,,,,,,,
,35023736.69,69953,10.0006499290466,250.051801147461,90.0139999389648,,,,,,,,,,,,,0,,,,,,0.1612,,,,,,,,,,
,35024071.50,69953,9.9992504119873,294.87927734375,90.0139999389648,,,,,,,,,,,,,0,,,,,,0.3175,,,,,,,,,,
,35024377.75,69953,10.0006499290466,339.985799560547,90.0139999389648,,,,,,,,,,,,,0,,,,,,0.6009,,,,,,,,,,
,35024692.45,69953,10.0003499984741,384.956960449219,90.0139999389648,,,,,,,,,,,,,0,,,,,,0.7132,,,,,,,,,,
,35025014.63,4417,9.99930000305176,375.031362304687,90.0139999389648,,,,,,,,,,,,,0,,,,,,0.8891,,,,,,,,,,
,35025328.28,69953,10.0002503395081,330.084361572266,90.0139999389648,,,,,,,,,,,,,0,,,,,,0.9624,,,,,,,,,,
,35025642.81,69953,9.99994993209839,284.998919677734,90.0139999389648,,,,,,,,,,,,,0,,,,,,0.9722,,,,,,,,,,
,35025970.91,4417,9.99935007095337,240.038719482422,90.0139999389648,,,,,,,,,,,,,0,,,,,,0.1172,,,,,,,,,,
,35026291.20,69953,10.0001497268677,195.089160766602,90.0139999389648,,,,,,,,,,,,,0,,,,,,0.2101,,,,,,,,,,
,35026626.69,69953,10.0002002716064,149.96255859375,90.0139999389648,,,,,,,,,,,,,0,,,,,,0.2980,,,,,,,,,,
,35026955.08,69953,10.0003499984741,105.009799804688,90.0139999389648,,,,,,,,,,,,,0,,,,,,0.7572,,,,,,,,,,
,35027269.47,69953,10.0001001358032,60.1113600158691,90.0139999389648,,,,,,,,,,,,,0,,,,,,0.7523,,,,,,,,,,
,35027583.50,4417,9.99995040893555,15.0706000518799,90.0139999389648,,,,,,,,,,,,,0,,,,,,0.8549,,,,,,,,,,
,35027897.98,69953,10.0001497268677,-29.9031600189209,90.0139999389648,,,,,,,,,,,,,0,,,,,,1.2506,,,,,,,,,,
,35028212.27,69953,10.0004000663757,-74.9175601196289,90.0139999389648,,,,,,,,,,,,,0,,,,,,1.0747,,,,,,,,,,
,35028519.77,4417,9.99969959259033,-119.878799743652,90.0139999389648,,,,,,,,,,,,,0,,,,,,-1.6854,,,,,,,,,,
,35028841.14,69953,10.0001001358032,-164.945280151367,90.0139999389648,,,,,,,,,,,,,0,,,,,,-1.9638,,,,,,,,,,
,35029168.95,69953,10.0005497932434,-210.007880249023,90.0139999389648,,,,,,,,,,,,,0,,,,,,0.7523,,,,,,,,,,
,35029483.36,4417,9.99979972839355,-254.873519897461,90.0139999389648,,,,,,,,,,,,,0,,,,,,1.0552,,,,,,,,,,
,35029797.89,69953,10.000500202179,-299.886721191406,90.0139999389648,,,,,,,,,,,,,0,,,,,,0.7523,,,,,,,,,,
,35030124.56,69953,10.0001001358032,-344.991882324219,90.0139999389648,,,,,,,,,,,,,0,,,,,,0.8891,,,,,,,,,,
,35030458.30,69953,10.0002999305725,-390.005640869141,90.0139999389648,,,,,,,,,,,,,0,,,,,,0.8842,,,,,,,,,,
,35030779.53,69953,9.99969959259033,-370.02916015625,90.0139999389648,,,,,,,,,,,,,0,,,,,,0.9086,,,,,,,,,,
,35031099.70,4417,9.9997501373291,-325.095040283203,90.0139999389648,,,,,,,,,,,,,0,,,,,,0.8598,,,,,,,,,,
,35031427.50,69953,10,-280.051999511719,90.0139999389648,,,,,,,,,,,,,0,,,,,,0.9575,,,,,,,,,,
,35031741.66,69953,10.0002002716064,-235.079360351563,90.0139999389648,,,,,,,,,,,,,0,,,,,,0.7523,,,,,,,,,,
,35032076.70,4417,9.99970006942749,-190.048480224609,90.0139999389648,,,,,,,,,,,,,0,,,,,,0.9673,,,,,,,,,,
,35032390.08,69953,10.0006999969482,-145.019800415039,90.0139999389648,,,,,,,,,,,,,0,,,,,,0.9135,,,,,,,,,,
,35032710.42,69953,9.99939966201782,-99.9683200073242,90.0139999389648,,,,,,,,,,,,,0,,,,,,1.0210,,,,,,,,,,
,35033024.42,4417,9.99959993362427,-55.074280090332,90.0139999389648,,,,,,,,,,,,,0,,,,,,0.8061,,,,,,,,,,
,35033331.83,69953,10.0004501342773,-10.0367599868774,90.0139999389648,,,,,,,,,,,,,0,,,,,,0.6595,,,,,,,,,,
,35033666.63,69953,10.0000495910645,35.0511601257324,90.0139999389648,,,,,,,,,,,,,0,,,,,,0.7230,,,,,,,,,,
,35033992.42,69953,9.99994993209839,80.0815997314453,90.0139999389648,,,,,,,,,,,,,0,,,,,,0.7767,,,,,,,,,,
,35034319.66,69953,10.0001502037048,124.952879943848,90.0139999389648,,,,,,,,,,,,,0,,,,,,-1.5535,,,,,,,,,,
,35034633.44,4417,9.99924993515015,169.97280090332,90.0139999389648,,,,,,,,,,,,,0,,,,,,-1.6854,,,,,,,,,,
,35034955.45,69953,10.0002999305725,214.98612121582,90.0139999389648,,,,,,,,,,,,,0,,,,,,1.1285,,,,,,,,,,
,35035271.27,69953,9.9997501373291,259.998120117188,90.0139999389648,,,,,,,,,,,,,0,,,,,,0.9380,,,,,,,,,,
,35035591.28,4417,10,304.946561279297,90.0139999389648,,,,,,,,,,,,,0,,,,,,1.0161,,,,,,,,,,
,35035898.44,69953,9.99970006942749,349.926842041016,90.0139999389648,,,,,,,,,,,,,0,,,,,,0.9722,,,,,,,,,,
,35036205.84,69953,10.0003499984741,394.950720214844,90.0139999389648,,,,,,,,,,,,,0,,,,,,0.9477,,,,,,,,,,
,35036505.95,4417,9.99924993515015,365.090363769531,90.0139999389648,,,,,,,,,,,,,0,,,,,,0.9038,,,,,,,,,,
,35036820.28,69953,10.0000996589661,320.092958984375,90.0139999389648,,,,,,,,,,,,,0,,,,,,0.8940,,,,,,,,,,
,35037134.89,69953,10.0000500679016,275.127598876953,90.0139999389648,,,,,,,,,,,,,0,,,,,,0.7377,,,,,,,,,,
,35037449.58,69953,10.0000500679016,230.042959594727,90.0139999389648,,,,,,,,,,,,,0,,,,,,0.7084,,,,,,,,,,
,35037756.36,69953,9.99990034103394,185.069239501953,90.0139999389648,,,,,,,,,,,,,0,,,,,,0.5960,,,,,,,,,,
,35038070.08,4417,10.0000500679016,140.109800415039,90.0139999389648,,,,,,,,,,,,,0,,,,,,0.5716,,,,,,,,,,
,35038391.22,69953,10.0007500648499,95.0602798461914,90.0139999389648,,,,,,,,,,,,,0,,,,,,0.7767,,,,,,,,,,
,35038698.89,69953,10.0004000663757,49.9937200927734,90.0139999389648,,,,,,,,,,,,,0,,,,,,0.6106,,,,,,,,,,
,35039027.70,4417,9.99959993362427,4.98643997192383,90.0139999389648,,,,,,,,,,,,,0,,,,,,0.9770,,,,,,,,,,
,35039355.66,69953,9.99965000152588,-40.0383201599121,90.0139999389648,,,,,,,,,,,,,0,,,,,,1.0161,,,,,,,,,,
,35039670.52,69953,9.99989986419678,-84.9599597167969,90.0139999389648,,,,,,,,,,,,,0,,,,,,-1.3923,,,,,,,,,,
,35039985.91,4417,9.99945020675659,-129.887838134766,90.0139999389648,,,,,,,,,,,,,0,,,,,,-1.7049,,,,,,,,,,
,35040300.17,69953,10.0002002716064,-174.875158081055,90.0139999389648,,,,,,,,,,,,,0,,,,,,-1.7538,,,,,,,,,,
,35040635.50,69953,10.0003004074097,-219.915200805664,90.0139999389648,,,,,,,,,,,,,0,,,,,,0.8842,,,,,,,,,,
,35040948.53,69953,9.99969959259033,-264.975400390625,90.0139999389648,,,,,,,,,,,,,0,,,,,,0.9331,,,,,,,,,,
,35041268.92,69953,10,-309.843120117187,90.0139999389648,,,,,,,,,,,,,0,,,,,,0.8109,,,,,,,,,,
,35041588.78,69953,9.99989986419678,-354.949476318359,90.0139999389648,,,,,,,,,,,,,0,,,,,,0.9086,,,,,,,,,,
,35041909.67,69953,10.0004496574402,-399.845841064453,90.0139999389648,,,,,,,,,,,,,0,,,,,,0.9184,,,,,,,,,,
,35042224.72,69953,9.99974966049194,-360.144678955078,90.0139999389648,,,,,,,,,,,,,0,,,,,,0.8354,,,,,,,,,,
,35042539.89,4417,9.99970006942749,-315.022282714844,90.0139999389648,,,,,,,,,,,,,0,,,,,,1.1627,,,,,,,,,,
,35042867.67,69953,9.99994993209839,-270.056599121094,90.0139999389648,,,,,,,,,,,,,0,,,,,,1.0992,,,,,,,,,,
,35043181.09,69953,10.0000996589661,-225.094840087891,90.0139999389648,,,,,,,,,,,,,0,,,,,,1.0992,,,,,,,,,,
,35043514.78,4417,9.9997501373291,-180.044000244141,90.0139999389648,,,,,,,,,,,,,0,,,,,,1.0503,,,,,,,,,,
,35043835.41,69953,10.0000500679016,-135.081240844727,90.0139999389648,,,,,,,,,,,,,0,,,,,,1.0161,,,,,,,,,,
,35044156.02,69953,10.0001502037048,-90.0108401489258,90.0139999389648,,,,,,,,,,,,,0,,,,,,1.0064,,,,,,,,,,
,35044463.73,69953,10.0001001358032,-44.9962803649902,90.0139999389648,,,,,,,,,,,,,0,,,,,,1.0992,,,,,,,,,,
,35044785.13,69953,9.99965000152588,0.0237599999830127,90.0139999389648,,,,,,,,,,,,,0,,,,,,0.9135,,,,,,,,,,
,35045127.56,4417,9.9995002746582,45.032200012207,90.0139999389648,,,,,,,,,,,,,0,,,,,,0.8696,,,,,,,,,,
,35045434.55,69953,9.99994993209839,89.972919921875,90.0139999389648,,,,,,,,,,,,,0,,,,,,0.6302,,,,,,,,,,
,35045755.11,69953,9.99970006942749,134.874241333008,90.0139999389648,,,,,,,,,,,,,0,,,,,,-1.7098,,,,,,,,,,
,35046063.13,4417,9.99970006942749,179.939198608398,90.0139999389648,,,,,,,,,,,,,0,,,,,,-1.6219,,,,,,,,,,
,35046389.98,69953,10.0004501342773,224.910159912109,90.0139999389648,,,,,,,,,,,,,0,,,,,,0.8451,,,,,,,,,,
,35046698.08,69953,10.0003499984741,269.877399902344,90.0139999389648,,,,,,,,,,,,,0,,,,,,0.8598,,,,,,,,,,
,35047025.09,4417,9.9995002746582,314.901882324219,90.0139999389648,,,,,,,,,,,,,0,,,,,,0.8940,,,,,,,,,,
,35047332.19,69953,10.0003499984741,359.921560058594,90.0139999389648,,,,,,,,,,,,,0,,,,,,0.9331,,,,,,,,,,
,35047632.31,69953,10.0000996589661,399.925599365234,90.0139999389648,,,,,,,,,,,,,0,,,,,,1.0259,,,,,,,,,,
,35047959.39,69953,10.0000500679016,355.066201171875,90.0139999389648,,,,,,,,,,,,,0,,,,,,1.0405,,,,,,,,,,
,35048273.33,69953,10.0001502037048,310.071000976563,90.0139999389648,,,,,,,,,,,,,0,,,,,,0.9624,,,,,,,,,,
,35048588.31,69953,10.0001497268677,265.180522460937,90.0139999389648,,,,,,,,,,,,,0,,,,,,0.7816,,,,,,,,,,
,35048922.14,69953,9.99985027313232,220.02251953125,90.0139999389648,,,,,,,,,,,,,0,,,,,,0.9673,,,,,,,,,,
,35049251.89,69953,10.0001001358032,175.008162231445,90.0139999389648,,,,,,,,,,,,,0,,,,,,0.9038,,,,,,,,,,
,35049566.63,4417,9.99965000152588,130.122200927734,90.0139999389648,,,,,,,,,,,,,0,,,,,,0.9380,,,,,,,,,,
,35049887.94,69953,10.0000500679016,85.0786795043945,90.0139999389648,,,,,,,,,,,,,0,,,,,,0.8109,,,,,,,,,,
,35050203.23,69953,9.99985027313232,39.9956800842285,90.0139999389648,,,,,,,,,,,,,0,,,,,,0.6742,,,,,,,,,,
,35050524.78,4417,9.99995040893555,-5.02364002227783,90.0139999389648,,,,,,,,,,,,,0,,,,,,0.7523,,,,,,,,,,
,35050839.09,69953,10.0002002716064,-49.9009201049805,90.0139999389648,,,,,,,,,,,,,0,,,,,,0.7670,,,,,,,,,,
,35051159.47,69953,10.0005497932434,-94.9223999023438,90.0139999389648,,,,,,,,,,,,,0,,,,,,-1.6707,,,,,,,,,,
,35051473.53,4417,9.99965000152588,-140.004639892578,90.0139999389648,,,,,,,,,,,,,0,,,,,,-1.8026,,,,,,,,,,
,35051781.36,69953,10.0001001358032,-184.956159057617,90.0139999389648,,,,,,,,,,,,,0,,,,,,1.0796,,,,,,,,,,
,35052115.81,69953,10.0006499290466,-229.92551940918,90.0139999389648,,,,,,,,,,,,,0,,,,,,0.9868,,,,,,,,,,
,35052436.13,69953,9.99970006942749,-274.885598144531,90.0139999389648,,,,,,,,,,,,,0,,,,,,0.9086,,,,,,,,,,
,35052763.52,69953,10.0002498626709,-319.87263671875,90.0139999389648,,,,,,,,,,,,,0,,,,,,0.9331,,,,,,,,,,
,35053090.91,4417,9.99994993209839,-364.997159423828,90.0139999389648,,,,,,,,,,,,,0,,,,,,0.8745,,,,,,,,,,
,35053413.73,69953,10.0002999305725,-394.955959472656,90.0139999389648,,,,,,,,,,,,,0,,,,,,0.9233,,,,,,,,,,
,35053728.48,69953,9.99980020523071,-350.12240234375,90.0139999389648,,,,,,,,,,,,,0,,,,,,0.7767,,,,,,,,,,
,35054049.30,4417,9.99995040893555,-305.130081787109,90.0139999389648,,,,,,,,,,,,,0,,,,,,0.7719,,,,,,,,,,
,35054400.05,69953,9.99984979629517,-259.919400634766,90.0139999389648,,,,,,,,,,,,,0,,,,,,0.7865,,,,,,,,,,
,35054707.17,69953,9.99985027313232,-215.003159179687,90.0139999389648,,,,,,,,,,,,,0,,,,,,0.8549,,,,,,,,,,
,35055035.22,69953,10.0005497932434,-169.960041503906,90.0139999389648,,,,,,,,,,,,,0,,,,,,0.9770,,,,,,,,,,
,35055347.91,69953,9.99979972839355,-125.009359130859,90.0139999389648,,,,,,,,,,,,,0,,,,,,0.8745,,,,,,,,,,
,35055655.31,69953,10.0000996589661,-80.0807604980469,90.0139999389648,,,,,,,,,,,,,0,,,,,,0.6546,,,,,,,,,,
,35055969.94,69953,10.0003004074097,-35.0168002319336,90.0139999389648,,,,,,,,,,,,,0,,,,,,0.7621,,,,,,,,,,
,35056304.73,69953,9.99959993362427,10.0496399307251,90.0139999389648,,,,,,,,,,,,,0,,,,,,0.5716,,,,,,,,,,
,35056626.94,4417,10.0000996589661,54.9025202941895,90.0139999389648,,,,,,,,,,,,,0,,,,,,0.6497,,,,,,,,,,
,35056942.14,69953,9.99994993209839,99.9923196411133,90.0139999389648,,,,,,,,,,,,,0,,,,,,-1.6610,,,,,,,,,,
,35057262.78,69953,10.0000500679016,145.02783996582,90.0139999389648,,,,,,,,,,,,,0,,,,,,-1.8026,,,,,,,,,,
,35057585.50,69953,9.99994993209839,189.880960693359,90.0139999389648,,,,,,,,,,,,,0,,,,,,-1.6707,,,,,,,,,,
,35057906.08,69953,10,234.876599121094,90.0139999389648,,,,,,,,,,,,,0,,,,,,0.9135,,,,,,,,,,
,35058232.38,69953,10.0001497268677,279.949278564453,90.0139999389648,,,,,,,,,,,,,0,,,,,,0.8793,,,,,,,,,,
,35058551.94,69953,10.0002498626709,324.982838134766,90.0139999389648,,,,,,,,,,,,,0,,,,,,1.0357,,,,,,,,,,
,35058859.78,69953,10.0002498626709,369.983000488281,90.0139999389648,,,,,,,,,,,,,0,,,,,,0.8793,,,,,,,,,,
,35059167.38,4417,9.99965000152588,390.080600585937,90.0139999389648,,,,,,,,,,,,,0,,,,,,0.8696,,,,,,,,,,
,35059489.16,69953,9.99959993362427,345.074519042969,90.0139999389648,,,,,,,,,,,,,0,,,,,,0.8940,,,,,,,,,,
,35059795.91,69953,10.0000500679016,300.08080078125,90.0139999389648,,,,,,,,,,,,,0,,,,,,0.7621,,,,,,,,,,
,35060110.52,4417,9.99965000152588,255.071118164063,90.0139999389648,,,,,,,,,,,,,0,,,,,,0.8256,,,,,,,,,,
,35060425.05,69953,10.0002999305725,210.112438964844,90.0139999389648,,,,,,,,,,,,,0,,,,,,0.7279,,,,,,,,,,
,35060745.98,69953,10.0004496574402,165.068040771484,90.0139999389648,,,,,,,,,,,,,0,,,,,,0.8647,,,,,,,,,,
,35061053.64,69953,10.0002002716064,120.107679443359,90.0139999389648,,,,,,,,,,,,,0,,,,,,0.8793,,,,,,,,,,
,35061374.73,69953,9.99985027313232,75.0464401245117,90.0139999389648,,,,,,,,,,,,,0,,,,,,0.7621,,,,,,,,,,
,35061688.27,4417,9.99949979782104,30.0362001037598,90.0139999389648,,,,,,,,,,,,,0,,,,,,0.7328,,,,,,,,,,
,35061994.50,69953,10.0001502037048,-14.920119972229,90.0139999389648,,,,,,,,,,,,,0,,,,,,0.6497,,,,,,,,,,
,35062307.86,69953,10.0004501342773,-59.9954402160645,90.0139999389648,,,,,,,,,,,,,0,,,,,,0.7084,,,,,,,,,,
,35062629.44,4417,9.99979972839355,-104.927040100098,90.0139999389648,,,,,,,,,,,,,0,,,,,,-1.7245,,,,,,,,,,
,35062936.63,69953,10.0001502037048,-149.832078857422,90.0139999389648,,,,,,,,,,,,,0,,,,,,-1.8661,,,,,,,,,,
,35063258.86,69953,10.0004496574402,-194.860361328125,90.0139999389648,,,,,,,,,,,,,0,,,,,,0.8354,,,,,,,,,,
,35063579.92,4417,9.99970006942749,-239.938321533203,90.0139999389648,,,,,,,,,,,,,0,,,,,,0.7963,,,,,,,,,,
,35063893.66,69953,10.0002503395081,-284.886558837891,90.0139999389648,,,,,,,,,,,,,0,,,,,,0.8158,,,,,,,,,,
,35064209.80,69953,9.99954986572266,-330.001478271484,90.0139999389648,,,,,,,,,,,,,0,,,,,,0.8647,,,,,,,,,,
,35064536.94,69953,10.0002002716064,-374.954279785156,90.0139999389648,,,,,,,,,,,,,0,,,,,,0.8061,,,,,,,,,,
,35064857.72,69953,10.0009999275208,-384.974599609375,90.0139999389648,,,,,,,,,,,,,0,,,,,,0.7279,,,,,,,,,,
,35065185.91,4417,9.99930000305176,-340.001080322266,90.0139999389648,,,,,,,,,,,,,0,,,,,,1.0308,,,,,,,,,,
,35065506.83,69953,10.0001001358032,-295.096402587891,90.0139999389648,,,,,,,,,,,,,0,,,,,,0.7767,,,,,,,,,,
,35065835.33,69953,10.0002999305725,-250.050481567383,90.0139999389648,,,,,,,,,,,,,0,,,,,,0.9086,,,,,,,,,,
,35066149.02,4417,9.99954986572266,-204.952319946289,90.0139999389648,,,,,,,,,,,,,0,,,,,,1.0943,,,,,,,,,,
,35066463.22,69953,10.000599861145,-160.074280395508,90.0139999389648,,,,,,,,,,,,,0,,,,,,0.8109,,,,,,,,,,
,35066777.03,69953,10.0001001358032,-115.032319335938,90.0139999389648,,,,,,,,,,,,,0,,,,,,0.7719,,,,,,,,,,
,35067090.78,69953,9.99994993209839,-70.0743600463867,90.0139999389648,,,,,,,,,,,,,0,,,,,,1.2750,,,,,,,,,,
,35067412.83,69953,9.99979972839355,-25.0558802032471,90.0139999389648,,,,,,,,,,,,,0,,,,,,0.9966,,,,,,,,,,
,35067734.00,4417,10.0002503395081,19.9560800170898,90.0139999389648,,,,,,,,,,,,,0,,,,,,0.9086,,,,,,,,,,
,35068047.50,69953,9.99994993209839,64.9300408935547,90.0139999389648,,,,,,,,,,,,,0,,,,,,0.9526,,,,,,,,,,
,35068361.11,69953,9.99935007095337,109.88859954834,90.0139999389648,,,,,,,,,,,,,0,,,,,,-1.4949,,,,,,,,,,
,35068689.50,4417,9.9997501373291,155.004080810547,90.0139999389648,,,,,,,,,,,,,0,,,,,,-1.5095,,,,,,,,,,
,35069003.14,69953,10.0000500679016,199.920401611328,90.0139999389648,,,,,,,,,,,,,0,,,,,,0.6790,,,,,,,,,,
,35069323.98,69953,10.000500202179,244.946520996094,90.0139999389648,,,,,,,,,,,,,0,,,,,,0.9477,,,,,,,,,,
,35069644.25,4417,9.99974966049194,289.982279052734,90.0139999389648,,,,,,,,,,,,,0,,,,,,0.8500,,,,,,,,,,
,35069957.55,69953,10.0000996589661,335.023640136719,90.0139999389648,,,,,,,,,,,,,0,,,,,,0.7328,,,,,,,,,,
,35070265.22,69953,9.99990034103394,379.977000732422,90.0139999389648,,,,,,,,,,,,,0,,,,,,0.9624,,,,,,,,,,
,35070571.88,4417,9.99909973144531,380.131278076172,90.0139999389648,,,,,,,,,,,,,0,,,,,,0.8891,,,,,,,,,,
,35070886.23,69953,9.99934959411621,335.042198486328,90.0139999389648,,,,,,,,,,,,,0,,,,,,1.0454,,,,,,,,,,
,35071201.94,69953,9.99970006942749,289.991680908203,90.0139999389648,,,,,,,,,,,,,0,,,,,,1.0357,,,,,,,,,,
,35071529.84,69953,9.9997501373291,245.158120727539,90.0139999389648,,,,,,,,,,,,,0,,,,,,0.9722,,,,,,,,,,
,35071852.20,69953,9.99980020523071,200.102600708008,90.0139999389648,,,,,,,,,,,,,0,,,,,,0.9038,,,,,,,,,,
,35072172.63,4417,9.99989986419678,155.113318481445,90.0139999389648,,,,,,,,,,,,,0,,,,,,0.9770,,,,,,,,,,
,35072501.19,69953,10.0001001358032,110.10656036377,90.0139999389648,,,,,,,,,,,,,0,,,,,,0.9233,,,,,,,,,,
,35072816.42,69953,10,65.0426000976562,90.0139999389648,,,,,,,,,,,,,0,,,,,,0.7426,,,,,,,,,,
,35073142.45,69953,9.99930000305176,19.9712802124023,90.0139999389648,,,,,,,,,,,,,0,,,,,,0.5178,,,,,,,,,,
,35073450.44,69953,10.0001502037048,-24.944400177002,90.0139999389648,,,,,,,,,,,,,0,,,,,,0.5520,,,,,,,,,,
,35073764.84,69953,10.0005502700806,-69.9660809326172,90.0139999389648,,,,,,,,,,,,,0,,,,,,0.4446,,,,,,,,,,
,35074086.11,69953,9.99974966049194,-114.865440979004,90.0139999389648,,,,,,,,,,,,,0,,,,,,-1.4802,,,,,,,,,,
,35074393.63,69953,9.99995040893555,-159.877319946289,90.0139999389648,,,,,,,,,,,,,0,,,,,,-1.7294,,,,,,,,,,
,35074729.66,4417,10.0002498626709,-204.949161376953,90.0139999389648,,,,,,,,,,,,,0,,,,,,1.2653,,,,,,,,,,
,35075044.25,69953,10.0002498626709,-249.937641601562,90.0139999389648,,,,,,,,,,,,,0,,,,,,0.8500,,,,,,,,,,
,35075352.05,69953,10,-294.987719726562,90.0139999389648,,,,,,,,,,,,,0,,,,,,0.8745,,,,,,,,,,
,35075673.75,4417,9.99970006942749,-339.981239013672,90.0139999389648,,,,,,,,,,,,,0,,,,,,1.0405,,,,,,,,,,
,35076010.19,69953,10.0004000663757,-384.861998291016,90.0139999389648,,,,,,,,,,,,,0,,,,,,1.0650,,,,,,,,,,
,35076324.78,69953,9.99990034103394,-374.959317626953,90.0139999389648,,,,,,,,,,,,,0,,,,,,1.0747,,,,,,,,,,
,35076646.19,69953,10,-329.986079101563,90.0139999389648,,,,,,,,,,,,,0,,,,,,1.0259,,,,,,,,,,
,35076966.97,69953,9.99989986419678,-284.996240234375,90.0139999389648,,,,,,,,,,,,,0,,,,,,1.0112,,,,,,,,,,
,35077287.45,4417,9.99965000152588,-239.958399658203,90.0139999389648,,,,,,,,,,,,,0,,,,,,1.0308,,,,,,,,,,
,35077608.41,69953,10.0002503395081,-194.999041137695,90.0139999389648,,,,,,,,,,,,,0,,,,,,0.8598,,,,,,,,,,
,35077922.27,69953,10.0002503395081,-150.160800170898,90.0139999389648,,,,,,,,,,,,,0,,,,,,0.9477,,,,,,,,,,
,35078243.36,4417,9.99909973144531,-104.93,90.0139999389648,,,,,,,,,,,,,0,,,,,,0.9819,,,,,,,,,,
,35078558.13,69953,10.0002498626709,-60.0062399291992,90.0139999389648,,,,,,,,,,,,,0,,,,,,0.9282,,,,,,,,,,
,35078880.41,69953,9.99980020523071,-14.9294799423218,90.0139999389648,,,,,,,,,,,,,0,,,,,,1.0503,,,,,,,,,,
,35079222.81,69953,10.0001997947693,29.9344801330566,90.0139999389648,,,,,,,,,,,,,0,,,,,,0.9233,,,,,,,,,,
,35079537.84,69953,9.9997501373291,74.9258395385742,90.0139999389648,,,,,,,,,,,,,0,,,,,,0.7523,,,,,,,,,,
,35079858.36,4417,9.99944972991943,120.02608001709,90.0139999389648,,,,,,,,,,,,,0,,,,,,-1.3874,,,,,,,,,,
,35080184.38,69953,10.0001502037048,165.077318725586,90.0139999389648,,,,,,,,,,,,,0,,,,,,-1.6561,,,,,,,,,,
,35080517.94,69953,10.0000500679016,209.924840698242,90.0139999389648,,,,,,,,,,,,,0,,,,,,1.1676,,,,,,,,,,
,35080832.94,69953,9.99995040893555,254.954358520508,90.0139999389648,,,,,,,,,,,,,0,,,,,,0.9770,,,,,,,,,,
,35081153.30,69953,9.9997501373291,299.994317626953,90.0139999389648,,,,,,,,,,,,,0,,,,,,0.8989,,,,,,,,,,
,35081473.86,4417,9.99884986877441,344.909317626953,90.0139999389648,,,,,,,,,,,,,0,,,,,,1.0454,,,,,,,,,,
,35081787.58,69953,10.0001502037048,389.893682861328,90.0139999389648,,,,,,,,,,,,,0,,,,,,1.1627,,,,,,,,,,
,35082088.16,69953,10.0002999305725,370.128082275391,90.0139999389648,,,,,,,,,,,,,0,,,,,,1.0405,,,,,,,,,,
,35082401.83,4417,9.99994993209839,324.999119873047,90.0139999389648,,,,,,,,,,,,,0,,,,,,0.9917,,,,,,,,,,
,35082723.91,69953,10.0004501342773,280.163959960938,90.0139999389648,,,,,,,,,,,,,0,,,,,,0.9380,,,,,,,,,,
,35083038.42,69953,9.99959993362427,235.086359863281,90.0139999389648,,,,,,,,,,,,,0,,,,,,0.9038,,,,,,,,,,
,35083352.17,4417,9.99930000305176,190.006241455078,90.0139999389648,,,,,,,,,,,,,0,,,,,,0.9770,,,,,,,,,,
,35083665.75,69953,9.99989986419678,145.147679443359,90.0139999389648,,,,,,,,,,,,,0,,,,,,1.0308,,,,,,,,,,
,35083980.30,4417,9.99959993362427,100.088440551758,90.0139999389648,,,,,,,,,,,,,0,,,,,,0.8256,,,,,,,,,,
,35084295.72,69953,10.0007500648499,55.084280090332,90.0139999389648,,,,,,,,,,,,,0,,,,,,0.8793,,,,,,,,,,
,35084616.88,69953,10.0003499984741,10.0438000106812,90.0139999389648,,,,,,,,,,,,,0,,,,,,0.8256,,,,,,,,,,
,35084931.53,4417,9.99969959259033,-34.9154399108887,90.0139999389648,,,,,,,,,,,,,0,,,,,,0.9428,,,,,,,,,,
,35085253.09,69953,9.99969959259033,-79.9775598144531,90.0139999389648,,,,,,,,,,,,,0,,,,,,-1.3923,,,,,,,,,,
,35085573.70,69953,9.9997501373291,-124.851719970703,90.0139999389648,,,,,,,,,,,,,0,,,,,,-1.5046,,,,,,,,,,
,35085881.38,4417,9.99944972991943,-169.965399780273,90.0139999389648,,,,,,,,,,,,,0,,,,,,-1.6365,,,,,,,,,,
,35086201.70,69953,10.0006999969482,-214.91,90.0139999389648,,,,,,,,,,,,,0,,,,,,1.1041,,,,,,,,,,
,35086516.36,69953,10.0000500679016,-259.940197753906,90.0139999389648,,,,,,,,,,,,,0,,,,,,1.1920,,,,,,,,,,
,35086837.64,69953,10.0002498626709,-305.025798339844,90.0139999389648,,,,,,,,,,,,,0,,,,,,1.1529,,,,,,,,,,
,35087165.34,69953,10.0002498626709,-349.974719238281,90.0139999389648,,,,,,,,,,,,,0,,,,,,1.1724,,,,,,,,,,
,35087486.25,4417,9.99959993362427,-394.877720947266,90.0139999389648,,,,,,,,,,,,,0,,,,,,0.9233,,,,,,,,,,
,35087806.92,69953,9.99980020523071,-365.025560302734,90.0139999389648,,,,,,,,,,,,,0,,,,,,1.1187,,,,,,,,,,
,35088141.61,69953,10.0003499984741,-320.031439208984,90.0139999389648,,,,,,,,,,,,,0,,,,,,1.1773,,,,,,,,,,
,35088469.41,69953,9.99985027313232,-275.021082763672,90.0139999389648,,,,,,,,,,,,,0,,,,,,0.8061,,,,,,,,,,
,35088782.92,69953,10,-230.110440063477,90.0139999389648,,,,,,,,,,,,,0,,,,,,0.8305,,,,,,,,,,
,35089096.81,69953,10.0000500679016,-185.071240844727,90.0139999389648,,,,,,,,,,,,,0,,,,,,0.8403,,,,,,,,,,
,35089418.19,69953,10,-139.981160888672,90.0139999389648,,,,,,,,,,,,,0,,,,,,0.9282,,,,,,,,,,
,35089746.20,69953,10.0006999969482,-94.9228802490234,90.0139999389648,,,,,,,,,,,,,0,,,,,,0.8451,,,,,,,,,,
,35090054.70,69953,10.0003499984741,-50.049040222168,90.0139999389648,,,,,,,,,,,,,0,,,,,,0.9086,,,,,,,,,,
,35090375.59,69953,10.0002002716064,-5.03187999725342,90.0139999389648,,,,,,,,,,,,,0,,,,,,0.4348,,,,,,,,,,
,35090712.95,69953,10,39.8882800292969,90.0139999389648,,,,,,,,,,,,,0,,,,,,0.6106,,,,,,,,,,
,35091026.08,4417,9.99994993209839,84.9645593261719,90.0139999389648,,,,,,,,,,,,,0,,,,,,0.4641,,,,,,,,,,
,35091346.14,69953,10.000500202179,130.016400146484,90.0139999389648,,,,,,,,,,,,,0,,,,,,-1.9003,,,,,,,,,,
,35091666.36,69953,10.0005502700806,175.018359375,90.0139999389648,,,,,,,,,,,,,0,,,,,,-2.0664,,,,,,,,,,
,35091993.42,69953,9.99979972839355,220.022678833008,90.0139999389648,,,,,,,,,,,,,0,,,,,,0.8696,,,,,,,,,,
,35092301.17,69953,10.0000500679016,264.909320068359,90.0139999389648,,,,,,,,,,,,,0,,,,,,0.8940,,,,,,,,,,
,35092622.39,4417,9.99970006942749,309.960601806641,90.0139999389648,,,,,,,,,,,,,0,,,,,,1.0747,,,,,,,,,,
,35092943.59,69953,10.0001502037048,354.886879882812,90.0139999389648,,,,,,,,,,,,,0,,,,,,0.9624,,,,,,,,,,
,35093265.02,69953,10.0002503395081,399.932637939453,90.0139999389648,,,,,,,,,,,,,0,,,,,,0.9477,,,,,,,,,,
,35093565.47,4417,9.99919986724854,360.033001708984,90.0139999389648,,,,,,,,,,,,,0,,,,,,0.8940,,,,,,,,,,
,35093871.92,69953,10.0004000663757,315.118918457031,90.0139999389648,,,,,,,,,,,,,0,,,,,,0.7719,,,,,,,,,,
,35094186.23,69953,9.99985027313232,269.999521484375,90.0139999389648,,,,,,,,,,,,,0,,,,,,0.8451,,,,,,,,,,
,35094501.56,69953,10.0000996589661,225.10467956543,90.0139999389648,,,,,,,,,,,,,0,,,,,,0.7670,,,,,,,,,,
,35094816.59,69953,10.0000495910645,179.941480102539,90.0139999389648,,,,,,,,,,,,,0,,,,,,0.9380,,,,,,,,,,
,35095124.14,69953,10.0002498626709,134.995960693359,90.0139999389648,,,,,,,,,,,,,0,,,,,,0.7865,,,,,,,,,,
,35095431.58,69953,10.0006999969482,90.1352001953125,90.0139999389648,,,,,,,,,,,,,0,,,,,,0.8207,,,,,,,,,,
,35095739.30,69953,10.0009503364563,45.0502000427246,90.0139999389648,,,,,,,,,,,,,0,,,,,,0.9380,,,,,,,,,,
,35096059.69,4417,10.0000500679016,0.106520000472665,90.0139999389648,,,,,,,,,,,,,0,,,,,,0.8207,,,,,,,,,,
,35096380.94,69953,9.99984979629517,-44.8960000610352,90.0139999389648,,,,,,,,,,,,,0,,,,,,0.8647,,,,,,,,,,
,35096702.64,69953,9.99974966049194,-90.0050402832031,90.0139999389648,,,,,,,,,,,,,0,,,,,,-1.5926,,,,,,,,,,
,35097016.83,4417,9.99990034103394,-134.885840454102,90.0139999389648,,,,,,,,,,,,,0,,,,,,-1.6903,,,,,,,,,,
,35097330.86,69953,9.99990034103394,-180.046198730469,90.0139999389648,,,,,,,,,,,,,0,,,,,,0.9038,,,,,,,,,,
,35097665.61,69953,10.0002002716064,-224.993999633789,90.0139999389648,,,,,,,,,,,,,0,,,,,,0.8207,,,,,,,,,,
,35097993.45,69953,9.99989986419678,-269.900200195312,90.0139999389648,,,,,,,,,,,,,0,,,,,,0.9673,,,,,,,,,,
,35098307.70,69953,10.0004997253418,-315.037121582031,90.0139999389648,,,,,,,,,,,,,0,,,,,,1.0161,,,,,,,,,,
,35098629.58,4417,9.99994993209839,-359.871882324219,90.0139999389648,,,,,,,,,,,,,0,,,,,,1.0503,,,,,,,,,,
,35098944.36,69953,10.0006499290466,-399.868118896484,90.0139999389648,,,,,,,,,,,,,0,,,,,,0.9624,,,,,,,,,,
,35099279.94,69953,10.0000500679016,-354.990596923828,90.0139999389648,,,,,,,,,,,,,0,,,,,,0.8940,,,,,,,,,,
,35099594.11,4417,9.99955034255981,-309.970198974609,90.0139999389648,,,,,,,,,,,,,0,,,,,,0.8109,,,,,,,,,,
,35099908.75,69953,9.9997501373291,-265.099599609375,90.0139999389648,,,,,,,,,,,,,0,,,,,,0.7719,,,,,,,,,,
,35100229.58,69953,10.0002002716064,-220.11123840332,90.0139999389648,,,,,,,,,,,,,0,,,,,,0.8745,,,,,,,,,,
,35100550.17,4417,9.99994993209839,-174.888959350586,90.0139999389648,,,,,,,,,,,,,0,,,,,,0.8549,,,,,,,,,,
,35100870.38,69953,10.0002999305725,-130.001041259766,90.0139999389648,,,,,,,,,,,,,0,,,,,,0.5667,,,,,,,,,,
,35101191.28,69953,10.0003499984741,-84.9494396972656,90.0139999389648,,,,,,,,,,,,,0,,,,,,0.6937,,,,,,,,,,
,35101505.16,69953,10.0001997947693,-40.075359954834,90.0139999389648,,,,,,,,,,,,,0,,,,,,0.7719,,,,,,,,,,
,35101832.41,69953,10.0001997947693,5.18848001480103,90.0139999389648,,,,,,,,,,,,,0,,,,,,0.6058,,,,,,,,,,
,35102152.16,4417,9.99930000305176,49.9250401306152,90.0139999389648,,,,,,,,,,,,,0,,,,,,0.9331,,,,,,,,,,
,35102466.38,69953,10,95.0468399047852,90.0139999389648,,,,,,,,,,,,,0,,,,,,-1.2018,,,,,,,,,,
,35102788.13,69953,10,139.918159179688,90.0139999389648,,,,,,,,,,,,,0,,,,,,-1.5095,,,,,,,,,,
,35103109.81,4417,10,185.084321289063,90.0139999389648,,,,,,,,,,,,,0,,,,,,-1.8515,,,,,,,,,,
,35103438.77,69953,10.0001497268677,229.924159545898,90.0139999389648,,,,,,,,,,,,,0,,,,,,0.8061,,,,,,,,,,
,35103766.16,69953,10.0002503395081,274.992919921875,90.0139999389648,,,,,,,,,,,,,0,,,,,,0.7377,,,,,,,,,,
,35104093.34,69953,10.0005497932434,320.001162109375,90.0139999389648,,,,,,,,,,,,,0,,,,,,0.7670,,,,,,,,,,
,35104407.78,69953,10.0000495910645,364.925283203125,90.0139999389648,,,,,,,,,,,,,0,,,,,,0.7328,,,,,,,,,,
,35104715.52,4417,9.99989986419678,395.076038818359,90.0139999389648,,,,,,,,,,,,,0,,,,,,0.9184,,,,,,,,,,
,35105023.05,69953,10.0006003379822,350.056037597656,90.0139999389648,,,,,,,,,,,,,0,,,,,,1.0552,,,,,,,,,,
,35105344.44,69953,9.99970006942749,305.108999023437,90.0139999389648,,,,,,,,,,,,,0,,,,,,0.9233,,,,,,,,,,
,35105672.94,4417,9.9997501373291,260.029477539063,90.0139999389648,,,,,,,,,,,,,0,,,,,,1.1041,,,,,,,,,,
,35105986.36,69953,10.0002503395081,215.02083984375,90.0139999389648,,,,,,,,,,,,,0,,,,,,0.9868,,,,,,,,,,
,35106313.78,69953,10.0000996589661,170.071080932617,90.0139999389648,,,,,,,,,,,,,0,,,,,,0.8793,,,,,,,,,,
,35106621.19,4417,9.99944972991943,125.157319335938,90.0139999389648,,,,,,,,,,,,,0,,,,,,0.8256,,,,,,,,,,
,35106941.47,69953,9.99989986419678,80.0990399169922,90.0139999389648,,,,,,,,,,,,,0,,,,,,0.9380,,,,,,,,,,
,35107261.66,69953,10.0001497268677,35.0567195129395,90.0139999389648,,,,,,,,,,,,,0,,,,,,0.7816,,,,,,,,,,
,35107576.33,69953,9.99989986419678,-9.92760005950928,90.0139999389648,,,,,,,,,,,,,0,,,,,,0.8500,,,,,,,,,,
,35107882.69,69953,9.99965000152588,-54.9673599243164,90.0139999389648,,,,,,,,,,,,,0,,,,,,0.9868,,,,,,,,,,
,35108197.41,69953,9.9997501373291,-99.9653192138672,90.0139999389648,,,,,,,,,,,,,0,,,,,,-1.6561,,,,,,,,,,
,35108510.47,69953,10.0004501342773,-145.021240844727,90.0139999389648,,,,,,,,,,,,,0,,,,,,-1.8026,,,,,,,,,,
,35108832.13,69953,9.99994993209839,-189.864239501953,90.0139999389648,,,,,,,,,,,,,0,,,,,,1.0259,,,,,,,,,,
,35109153.86,4417,9.9995002746582,-234.945080566406,90.0139999389648,,,,,,,,,,,,,0,,,,,,0.8696,,,,,,,,,,
,35109474.84,69953,9.99979972839355,-279.856596679688,90.0139999389648,,,,,,,,,,,,,0,,,,,,0.9380,,,,,,,,,,
,35109803.41,69953,10.0001502037048,-324.911879882813,90.0139999389648,,,,,,,,,,,,,0,,,,,,1.1383,,,,,,,,,,
,35110124.05,4417,9.99970006942749,-369.929479980469,90.0139999389648,,,,,,,,,,,,,0,,,,,,1.0796,,,,,,,,,,
,35110431.59,69953,10.0001502037048,-390.146276855469,90.0139999389648,,,,,,,,,,,,,0,,,,,,1.0259,,,,,,,,,,
,35110765.94,69953,9.99984979629517,-345.010559082031,90.0139999389648,,,,,,,,,,,,,0,,,,,,1.0601,,,,,,,,,,
,35111088.28,4417,9.99930000305176,-300.019721679688,90.0139999389648,,,,,,,,,,,,,0,,,,,,0.8891,,,,,,,,,,
,35111401.78,69953,10.0002002716064,-254.995,90.0139999389648,,,,,,,,,,,,,0,,,,,,0.9086,,,,,,,,,,
,35111716.83,69953,9.99945020675659,-210.127559814453,90.0139999389648,,,,,,,,,,,,,0,,,,,,0.9966,,,,,,,,,,
,35112044.22,69953,10.0004501342773,-165.072080688477,90.0139999389648,,,,,,,,,,,,,0,,,,,,1.0601,,,,,,,,,,
,35112364.27,69953,10.0001001358032,-119.993959960938,90.0139999389648,,,,,,,,,,,,,0,,,,,,0.9331,,,,,,,,,,
,35112698.44,4417,9.99930000305176,-74.9038397216797,90.0139999389648,,,,,,,,,,,,,0,,,,,,0.8745,,,,,,,,,,
,35113012.36,69953,9.99994993209839,-30.1001600646973,90.0139999389648,,,,,,,,,,,,,0,,,,,,0.6644,,,,,,,,,,
,35113340.52,69953,9.99994993209839,14.9557999801636,90.0139999389648,,,,,,,,,,,,,0,,,,,,0.8549,,,,,,,,,,
,35113656.52,4417,9.99949979782104,59.9917199707031,90.0139999389648,,,,,,,,,,,,,0,,,,,,0.5374,,,,,,,,,,
,35113963.58,69953,10.0003499984741,104.903400878906,90.0139999389648,,,,,,,,,,,,,0,,,,,,-1.8173,,,,,,,,,,
,35114284.88,69953,10.0002503395081,149.874559936523,90.0139999389648,,,,,,,,,,,,,0,,,,,,-1.8026,,,,,,,,,,
,35114605.52,4417,9.99930000305176,195.02032043457,90.0139999389648,,,,,,,,,,,,,0,,,,,,0.6839,,,,,,,,,,
,35114919.28,69953,10.0002498626709,239.953079833984,90.0139999389648,,,,,,,,,,,,,0,,,,,,0.7719,,,,,,,,,,
,35115226.64,69953,10.0002498626709,285.024400634766,90.0139999389648,,,,,,,,,,,,,0,,,,,,0.7523,,,,,,,,,,
,35115533.19,4417,9.99954986572266,330.092281494141,90.0139999389648,,,,,,,,,,,,,0,,,,,,0.7719,,,,,,,,,,
,35115840.14,69953,10.0005502700806,374.922916259766,90.0139999389648,,,,,,,,,,,,,0,,,,,,0.8012,,,,,,,,,,
,35116148.89,69953,10.0002498626709,385.076080322266,90.0139999389648,,,,,,,,,,,,,0,,,,,,0.6497,,,,,,,,,,
,35116475.73,4417,9.99954986572266,340.080798339844,90.0139999389648,,,,,,,,,,,,,0,,,,,,1.0112,,,,,,,,,,
,35116783.20,69953,9.99994993209839,295.066599121094,90.0139999389648,,,,,,,,,,,,,0,,,,,,0.8647,,,,,,,,,,
,35117105.61,69953,10.0001502037048,250.041478881836,90.0139999389648,,,,,,,,,,,,,0,,,,,,0.5227,,,,,,,,,,
,35117413.30,69953,10,205.060040893555,90.0139999389648,,,,,,,,,,,,,0,,,,,,0.7767,,,,,,,,,,
,35117733.31,69953,10.0000500679016,160.019080200195,90.0139999389648,,,,,,,,,,,,,0,,,,,,0.7377,,,,,,,,,,
,35118047.34,69953,9.99965000152588,114.981799926758,90.0139999389648,,,,,,,,,,,,,0,,,,,,0.7767,,,,,,,,,,
,35118368.17,69953,10.0005497932434,70.084479675293,90.0139999389648,,,,,,,,,,,,,0,,,,,,0.6937,,,,,,,,,,
,35118689.08,69953,9.99989986419678,25.0755198669434,90.0139999389648,,,,,,,,,,,,,0,,,,,,0.6302,,,,,,,,,,
,35118994.98,4417,9.99940013885498,-20.0335598754883,90.0139999389648,,,,,,,,,,,,,0,,,,,,0.6497,,,,,,,,,,
,35119308.33,69953,10.0006003379822,-64.9205200195313,90.0139999389648,,,,,,,,,,,,,0,,,,,,0.8207,,,,,,,,,,
,35119616.06,69953,9.99994993209839,-109.909640197754,90.0139999389648,,,,,,,,,,,,,0,,,,,,-1.7978,,,,,,,,,,
,35119937.34,4417,9.99979972839355,-154.889880371094,90.0139999389648,,,,,,,,,,,,,0,,,,,,-1.6952,,,,,,,,,,
,35120271.31,69953,10.0003499984741,-199.992680664063,90.0139999389648,,,,,,,,,,,,,0,,,,,,0.9135,,,,,,,,,,
,35120585.05,69953,9.99980020523071,-244.838681030273,90.0139999389648,,,,,,,,,,,,,0,,,,,,0.9526,,,,,,,,,,
,35120906.72,4417,9.99994993209839,-289.911641845703,90.0139999389648,,,,,,,,,,,,,0,,,,,,1.0064,,,,,,,,,,
,35121220.28,69953,9.99985027313232,-334.957359619141,90.0139999389648,,,,,,,,,,,,,0,,,,,,0.9673,,,,,,,,,,
,35121542.03,69953,10.0001997947693,-379.876960449219,90.0139999389648,,,,,,,,,,,,,0,,,,,,1.0503,,,,,,,,,,
,35121855.45,4417,9.99959993362427,-380.170638427734,90.0139999389648,,,,,,,,,,,,,0,,,,,,1.2018,,,,,,,,,,
,35122184.36,69953,10.0000500679016,-335.048599853516,90.0139999389648,,,,,,,,,,,,,0,,,,,,1.1822,,,,,,,,,,
,35122504.09,69953,10.0002503395081,-290.071640625,90.0139999389648,,,,,,,,,,,,,0,,,,,,1.2311,,,,,,,,,,
,35122825.41,69953,10.0001001358032,-245.044599609375,90.0139999389648,,,,,,,,,,,,,0,,,,,,1.0308,,,,,,,,,,
,35123145.81,69953,10.0000996589661,-200.136480712891,90.0139999389648,,,,,,,,,,,,,0,,,,,,1.0308,,,,,,,,,,
,35123459.97,4417,9.99979972839355,-154.99971862793,90.0139999389648,,,,,,,,,,,,,0,,,,,,1.0699,,,,,,,,,,
,35123780.56,69953,9.99959993362427,-110.045639953613,90.0139999389648,,,,,,,,,,,,,0,,,,,,1.0357,,,,,,,,,,
,35124093.61,69953,9.99984979629517,-65.1024801635742,90.0139999389648,,,,,,,,,,,,,0,,,,,,0.8989,,,,,,,,,,
,35124407.14,4417,9.9997501373291,-20.128440246582,90.0139999389648,,,,,,,,,,,,,0,,,,,,0.9038,,,,,,,,,,
,35124727.72,69953,10.0001502037048,25.0835200500488,90.0139999389648,,,,,,,,,,,,,0,,,,,,0.9184,,,,,,,,,,
,35125055.72,69953,10.0001997947693,69.9370394897461,90.0139999389648,,,,,,,,,,,,,0,,,,,,0.8158,,,,,,,,,,
,35125371.92,4417,9.99979972839355,114.884959716797,90.0139999389648,,,,,,,,,,,,,0,,,,,,-1.2506,,,,,,,,,,
,35125693.19,69953,10.0001502037048,160.000518798828,90.0139999389648,,,,,,,,,,,,,0,,,,,,-1.4460,,,,,,,,,,
,35126020.89,69953,10.0002498626709,204.961398925781,90.0139999389648,,,,,,,,,,,,,0,,,,,,1.1236,,,,,,,,,,
,35126328.45,4417,9.99914979934692,250.042520141602,90.0139999389648,,,,,,,,,,,,,0,,,,,,1.0552,,,,,,,,,,
,35126657.64,69953,9.99994993209839,295.052041015625,90.0139999389648,,,,,,,,,,,,,0,,,,,,1.1431,,,,,,,,,,
,35126965.17,69953,9.99954986572266,339.957838134766,90.0139999389648,,,,,,,,,,,,,0,,,,,,1.2018,,,,,,,,,,
,35127278.17,69953,9.99994993209839,384.950159912109,90.0139999389648,,,,,,,,,,,,,0,,,,,,1.1969,,,,,,,,,,
,35127585.44,69953,10.0001997947693,375.055239257813,90.0139999389648,,,,,,,,,,,,,0,,,,,,1.2066,,,,,,,,,,
,35127893.27,69953,10.0002999305725,330.097279052734,90.0139999389648,,,,,,,,,,,,,0,,,,,,1.1041,,,,,,,,,,
,35128199.66,69953,9.99994993209839,285.120158691406,90.0139999389648,,,,,,,,,,,,,0,,,,,,1.0308,,,,,,,,,,
,35128522.06,69953,9.9997501373291,240.07119934082,90.0139999389648,,,,,,,,,,,,,0,,,,,,1.0064,,,,,,,,,,
,35128837.38,4417,9.99994993209839,195.114039916992,90.0139999389648,,,,,,,,,,,,,0,,,,,,1.1676,,,,,,,,,,
,35129171.58,69953,9.99949979782104,149.969840087891,90.0139999389648,,,,,,,,,,,,,0,,,,,,1.0699,,,,,,,,,,
,35129485.25,69953,10.0000500679016,105.020480041504,90.0139999389648,,,,,,,,,,,,,0,,,,,,0.9575,,,,,,,,,,
,35129791.95,4417,9.99984979629517,60.0164404296875,90.0139999389648,,,,,,,,,,,,,0,,,,,,1.0503,,,,,,,,,,
,35130106.53,69953,10.0001001358032,15.0867999649048,90.0139999389648,,,,,,,,,,,,,0,,,,,,1.0064,,,,,,,,,,
,35130419.61,69953,9.99994993209839,-29.9153201293945,90.0139999389648,,,,,,,,,,,,,0,,,,,,0.9673,,,,,,,,,,
,35130741.17,4417,9.99969959259033,-74.8888800048828,90.0139999389648,,,,,,,,,,,,,0,,,,,,1.0112,,,,,,,,,,
,35131047.67,69953,10.0002999305725,-119.877759399414,90.0139999389648,,,,,,,,,,,,,0,,,,,,-1.3141,,,,,,,,,,
,35131354.94,69953,10.0003995895386,-164.942238769531,90.0139999389648,,,,,,,,,,,,,0,,,,,,-1.4558,,,,,,,,,,
,35131675.69,4417,9.9997501373291,-210.028240356445,90.0139999389648,,,,,,,,,,,,,0,,,,,,1.1480,,,,,,,,,,
,35132004.77,69953,10.0002498626709,-254.88223815918,90.0139999389648,,,,,,,,,,,,,0,,,,,,0.9184,,,,,,,,,,
,35132318.31,69953,9.99984979629517,-299.876038818359,90.0139999389648,,,,,,,,,,,,,0,,,,,,0.9673,,,,,,,,,,
,35132645.95,69953,10.0000500679016,-345.014639892578,90.0139999389648,,,,,,,,,,,,,0,,,,,,1.0259,,,,,,,,,,
,35132980.39,69953,9.99994993209839,-389.994197998047,90.0139999389648,,,,,,,,,,,,,0,,,,,,1.2897,,,,,,,,,,
,35133063.44,69953,10.0003004074097,-400.058559570313,90.0139999389648,,,,,,,,,,,,,0,,,,,,1.1920,,,,,,,,,,